<?xml version="1.0" ?>
<!-- =================================================================================== -->
<!-- |    This document was autogenerated by xacro from /home/hayashi/thesis_work/ros2/ros2_ws/install/bunker_unity/share/bunker_unity/urdf/bunker.urdf.xacro | -->
<!-- |    EDITING THIS FILE BY HAND IS NOT RECOMMENDED                                 | -->
<!-- =================================================================================== -->
<!-- Basic differential drive mobile base -->
<robot name="Bunker">
  <material name="velodyne_outside">
    <color rgba="0.95 0.95 0.95 1"/>
  </material>
  <material name="velodyne_glass">
    <color rgba="0.0 0.15 0.0 1"/>
  </material>
  <material name="emlid_top">
    <color rgba="0.95 0.95 0.95 1"/>
  </material>
  <material name="emlid_name">
    <color rgba="0.38 0.69 0.89 1"/>
  </material>
  <material name="emlid_bottom">
    <color rgba="0.4 0.4 0.4 1"/>
  </material>
  <material name="realsense_struct">
    <color rgba="0.95 0.95 0.95 1"/>
  </material>
  <material name="realsense_screen">
    <color rgba="0.10 0 0.10 1"/>
  </material>
  <material name="blue">
    <color rgba="0 0 0.75 1"/>
  </material>
  <material name="red">
    <color rgba="0.75 0 0 1"/>
  </material>
  <material name="white">
    <color rgba="1.0 1.0 1.0 1"/>
  </material>
  <material name="black">
    <color rgba="0 0 0 1"/>
  </material>
  <material name="alu">
    <color rgba="0.80 0.80 0.80 1"/>
  </material>
  <physics_material name="wheel">
    <friction dynamic="0.01" static="0.01"/>
  </physics_material>
  <link name="base_link">
    <inertial>
      <origin rpy="0 0 0" xyz="0 0 0"/>
      <mass value="0.01"/>
      <inertia ixx="0.0001" ixy="0.0" ixz="0.0" iyy="0.0001" iyz="0.0" izz="0.0001"/>
    </inertial>
  </link>
  <joint name="body_joint" type="fixed">
    <parent link="base_link"/>
    <child link="body_link"/>
    <origin rpy="0 0 0" xyz="0 0 -0.06"/>
  </joint>
  <link name="body_link">
    <inertial>
      <origin rpy="0 0 3.141592653589793" xyz="0 0 0"/>
      <mass value="30"/>
      <inertia ixx="0.001" ixy="0.0" ixz="0.0" iyy="0.001" iyz="0.0" izz="0.001"/>
    </inertial>
    <visual>
      <origin rpy="0 0 3.141592653589793" xyz="0 0 0"/>
      <geometry>
        <mesh filename="package://bunker_unity/meshes/chassis_blanc.stl" scale="1 1 1"/>
      </geometry>
      <material name="white"/>
    </visual>
    <collision>
      <origin rpy="0 0 3.141592653589793" xyz="0.05 0 0.115"/>
      <geometry>
        <mesh filename="package://bunker_unity/meshes/bunker_collision.stl" scale="0.4 0.4 0.4"/>
      </geometry>
    </collision>
  </link>
  <joint name="chassis_black_joint" type="fixed">
    <parent link="body_link"/>
    <child link="chassis_black_link"/>
    <origin rpy="0 0 0" xyz="0 0 0"/>
  </joint>
  <link name="chassis_black_link">
    <visual>
      <origin rpy="0 0 3.141592653589793" xyz="0 0 0"/>
      <geometry>
        <mesh filename="package://bunker_unity/meshes/chassis_black.stl" scale="1 1 1"/>
      </geometry>
      <material name="black"/>
    </visual>
    <inertial>
      <origin rpy="0 0 3.141592653589793" xyz="0 0 0"/>
      <mass value="50"/>
      <inertia ixx="0.001" ixy="0.0" ixz="0.0" iyy="0.001" iyz="0.0" izz="0.001"/>
    </inertial>
  </link>
  <joint name="chassis_red_joint" type="fixed">
    <parent link="body_link"/>
    <child link="chassis_red_link"/>
    <origin rpy="0 0 0" xyz="0 0 0"/>
  </joint>
  <link name="chassis_red_link">
    <visual>
      <origin rpy="0 0 3.141592653589793" xyz="0 0 0"/>
      <geometry>
        <mesh filename="package://bunker_unity/meshes/chassis_red.stl" scale="1 1 1"/>
      </geometry>
      <material name="red"/>
    </visual>
    <inertial>
      <origin rpy="0 0 3.141592653589793" xyz="0 0 0"/>
      <mass value="10"/>
      <inertia ixx="0.001" ixy="0.0" ixz="0.0" iyy="0.001" iyz="0.0" izz="0.001"/>
    </inertial>
  </link>
  <joint name="chassis_struct_joint" type="fixed">
    <parent link="body_link"/>
    <child link="chassis_struct_link"/>
    <origin rpy="0 0 0" xyz="0.18 0.19 0.52"/>
  </joint>
  <link name="chassis_struct_link">
    <visual>
      <origin rpy="0 0 0" xyz="0 0 0"/>
      <geometry>
        <mesh filename="package://bunker_unity/meshes/struct.stl" scale="1 1 1"/>
      </geometry>
      <material name="alu"/>
    </visual>
    <inertial>
      <origin rpy="0 0 0" xyz="0 0 0"/>
      <mass value="3"/>
      <inertia ixx="0.001" ixy="0.0" ixz="0.0" iyy="0.001" iyz="0.0" izz="0.001"/>
    </inertial>
    <collision>
      <origin rpy="0 0 3.141592653589793" xyz="0.05 -0.19 -0.08"/>
      <geometry>
        <mesh filename="package://bunker_unity/meshes/struct_collision.stl" scale="1 1 1"/>
      </geometry>
    </collision>
  </link>
  <joint name="velodyne_VLP16_joint" type="fixed">
    <parent link="body_link"/>
    <child link="velodyne_VLP16_link"/>
    <origin rpy="0 0 0" xyz="0.18 0 1.57"/>
  </joint>
  <link name="velodyne_VLP16_link">
    <unity_sensor gaussian_noise_sigma="0.02" max_intensity="255" max_range="100.0" min_range="0.5" points_num_per_scan="57600" publishing_frequency="10" sensor_frequency="20" topic_name="/velodyne_points" type="vlp16"/>
  </link>
  <joint name="velodyne_outside_joint" type="fixed">
    <parent link="velodyne_VLP16_link"/>
    <child link="velodyne_outside_link"/>
    <origin rpy="0 0 0" xyz="0 0 0"/>
  </joint>
  <link name="velodyne_outside_link">
    <visual>
      <origin rpy="0 0 0" xyz="0 0 0"/>
      <geometry>
        <mesh filename="package://bunker_unity/meshes/Sensors/Velodyne_VLP16/VLP16_outside.stl" scale="1 1 1"/>
      </geometry>
      <material name="velodyne_outside"/>
    </visual>
    <inertial>
      <origin rpy="0 0 0" xyz="0 0 0"/>
      <mass value="3"/>
      <inertia ixx="0.001" ixy="0.0" ixz="0.0" iyy="0.001" iyz="0.0" izz="0.001"/>
    </inertial>
  </link>
  <joint name="velodyne_glass_joint" type="fixed">
    <parent link="velodyne_VLP16_link"/>
    <child link="velodyne_glass_link"/>
    <origin rpy="0 0 0" xyz="0 0 0"/>
  </joint>
  <link name="velodyne_glass_link">
    <visual>
      <origin rpy="0 0 0" xyz="0 0 0"/>
      <geometry>
        <mesh filename="package://bunker_unity/meshes/Sensors/Velodyne_VLP16/VLP16_glass.stl" scale="1.01 1.01 1.01"/>
      </geometry>
      <material name="velodyne_glass"/>
    </visual>
    <inertial>
      <origin rpy="0 0 0" xyz="0 0 0"/>
      <mass value="3"/>
      <inertia ixx="0.001" ixy="0.0" ixz="0.0" iyy="0.001" iyz="0.0" izz="0.001"/>
    </inertial>
  </link>
  <joint name="velodyne_name_joint" type="fixed">
    <parent link="velodyne_VLP16_link"/>
    <child link="velodyne_name_link"/>
    <origin rpy="0 0 -1.5707963267948966" xyz="0 0 0"/>
  </joint>
  <link name="velodyne_name_link">
    <visual>
      <origin rpy="0 0 0" xyz="0 0 0"/>
      <geometry>
        <mesh filename="package://bunker_unity/meshes/Sensors/Velodyne_VLP16/VLP16_name.stl" scale="1 1 1"/>
      </geometry>
      <material name="black"/>
    </visual>
    <inertial>
      <origin rpy="0 0 0" xyz="0 0 0"/>
      <mass value="3"/>
      <inertia ixx="0.001" ixy="0.0" ixz="0.0" iyy="0.001" iyz="0.0" izz="0.001"/>
    </inertial>
  </link>
  <joint name="emlid_GNSS_joint" type="fixed">
    <parent link="body_link"/>
    <child link="emlid_GNSS_link"/>
    <origin rpy="0 0 0" xyz="0.30 0 1.22"/>
  </joint>
  <link name="emlid_GNSS_link">
    <unity_sensor publishing_frequency="10" sensor_frequency="10" topic_name="/navsat" type="gnss"/>
  </link>
  <joint name="emlid_GNSS_top_joint" type="fixed">
    <parent link="emlid_GNSS_link"/>
    <child link="emlid_GNSS_top_link"/>
    <origin rpy="0 0 1.5707963267948966" xyz="0 0 0"/>
  </joint>
  <link name="emlid_GNSS_top_link">
    <visual>
      <origin rpy="0 0 0" xyz="0 0 0"/>
      <geometry>
        <mesh filename="package://bunker_unity/meshes/Sensors/EMLID_GNSS/EMLID_top.stl" scale="1 1 1"/>
      </geometry>
      <material name="emlid_top"/>
    </visual>
    <inertial>
      <origin rpy="0 0 0" xyz="0 0 0"/>
      <mass value="3"/>
      <inertia ixx="0.001" ixy="0.0" ixz="0.0" iyy="0.001" iyz="0.0" izz="0.001"/>
    </inertial>
  </link>
  <joint name="emlid_GNSS_bottom_joint" type="fixed">
    <parent link="emlid_GNSS_link"/>
    <child link="emlid_GNSS_bottom_link"/>
    <origin rpy="0 0 1.5707963267948966" xyz="0 0 0"/>
  </joint>
  <link name="emlid_GNSS_bottom_link">
    <visual>
      <origin rpy="0 0 0" xyz="0 0 0"/>
      <geometry>
        <mesh filename="package://bunker_unity/meshes/Sensors/EMLID_GNSS/EMLID_bottom.stl" scale="1 1 1"/>
      </geometry>
      <material name="emlid_bottom"/>
    </visual>
    <inertial>
      <origin rpy="0 0 0" xyz="0 0 0"/>
      <mass value="3"/>
      <inertia ixx="0.001" ixy="0.0" ixz="0.0" iyy="0.001" iyz="0.0" izz="0.001"/>
    </inertial>
  </link>
  <joint name="emlid_GNSS_name_joint" type="fixed">
    <parent link="emlid_GNSS_link"/>
    <child link="emlid_GNSS_name_link"/>
    <origin rpy="0 0 1.5707963267948966" xyz="0 0 0"/>
  </joint>
  <link name="emlid_GNSS_name_link">
    <visual>
      <origin rpy="0 0 0" xyz="0 0 0"/>
      <geometry>
        <mesh filename="package://bunker_unity/meshes/Sensors/EMLID_GNSS/EMLID_Logo.stl" scale="1 1 1"/>
      </geometry>
      <material name="emlid_name"/>
    </visual>
    <inertial>
      <origin rpy="0 0 0" xyz="0 0 0"/>
      <mass value="3"/>
      <inertia ixx="0.001" ixy="0.0" ixz="0.0" iyy="0.001" iyz="0.0" izz="0.001"/>
    </inertial>
  </link>
  <joint name="D455_Camera_joint" type="fixed">
    <parent link="body_link"/>
    <child link="D455_Camera_link"/>
    <origin rpy="1.5707963267948966 0 1.5707963267948966" xyz="0.39 -0.13 0.83"/>
  </joint>
  <link name="D455_Camera_link"/>
  <joint name="D455_Cam_RGB_joint" type="fixed">
    <parent link="D455_Camera_link"/>
    <child link="D455_Cam_RGB_link"/>
    <origin rpy="0 -1.5707963267948966 -1.5707963267948966" xyz="0 0 0.02"/>
  </joint>
  <link name="D455_Cam_RGB_link">
    <unity_sensor fov="30" image_topic_name="/D455_camera/color/image/compressed" info_topic_name="/D455_camera/color/info" max_range="100" min_range="0.05" publishing_frequency="10" quality="75" res_x="640" res_y="480" sensor_frequency="20" type="camera_RGB"/>
    <inertial>
      <origin rpy="0 0 0" xyz="0 0 0"/>
      <mass value="0.1"/>
      <inertia ixx="0.001" ixy="0.0" ixz="0.0" iyy="0.001" iyz="0.0" izz="0.001"/>
    </inertial>
  </link>
  <joint name="D455_Cam_Depth_joint" type="fixed">
    <parent link="D455_Camera_link"/>
    <child link="D455_Cam_Depth_link"/>
    <origin rpy="0 -1.5707963267948966 -1.5707963267948966" xyz="0 0 0.02"/>
  </joint>
  <link name="D455_Cam_Depth_link">
    <unity_sensor PC_topic_name="/D455_camera/depth/points" fov="30" image_topic_name="/D455_camera/depth/image/compressed" info_topic_name="/D455_camera/depth/info" max_range="20" min_range="0.05" publishing_frequency="10" quality="75" res_x="640" res_y="480" sensor_frequency="20" type="camera_Depth"/>
    <inertial>
      <origin rpy="0 0 0" xyz="0 0 0"/>
      <mass value="0.1"/>
      <inertia ixx="0.001" ixy="0.0" ixz="0.0" iyy="0.001" iyz="0.0" izz="0.001"/>
    </inertial>
  </link>
  <joint name="D455_Camera_struct_joint" type="fixed">
    <parent link="D455_Camera_link"/>
    <child link="D455_Camera_struct_link"/>
    <origin rpy="0 0 0" xyz="0 0 0"/>
  </joint>
  <link name="D455_Camera_struct_link">
    <visual>
      <origin rpy="0 0 0" xyz="0 0 0"/>
      <geometry>
        <mesh filename="package://bunker_unity/meshes/Sensors/Realsense_D455/Realsense_D455.stl" scale="1 1 1"/>
      </geometry>
      <material name="realsense_struct"/>
    </visual>
    <inertial>
      <origin rpy="0 0 0" xyz="0 0 0"/>
      <mass value="0.1"/>
      <inertia ixx="0.001" ixy="0.0" ixz="0.0" iyy="0.001" iyz="0.0" izz="0.001"/>
    </inertial>
  </link>
  <joint name="D455_Camera_screen_joint" type="fixed">
    <parent link="D455_Camera_link"/>
    <child link="D455_Camera_screen_link"/>
    <origin rpy="0 0 0" xyz="0 0 0"/>
  </joint>
  <link name="D455_Camera_screen_link">
    <visual>
      <origin rpy="0 0 0" xyz="0 0 0"/>
      <geometry>
        <mesh filename="package://bunker_unity/meshes/Sensors/Realsense_D455/Realsense_D455_Screen.stl" scale="1 1 1"/>
      </geometry>
      <material name="realsense_screen"/>
    </visual>
    <inertial>
      <origin rpy="0 0 0" xyz="0 0 0"/>
      <mass value="0.1"/>
      <inertia ixx="0.001" ixy="0.0" ixz="0.0" iyy="0.001" iyz="0.0" izz="0.001"/>
    </inertial>
  </link>
  <joint name="xsens_imu_joint" type="fixed">
    <parent link="body_link"/>
    <child link="xsens_imu_link"/>
    <origin rpy="0 0 0" xyz="0.335 0.13 0.845"/>
  </joint>
  <link name="xsens_imu_link">
    <unity_sensor publishing_frequency="20" sensor_frequency="20" topic_name="/imu" type="imu"/>
  </link>
  <joint name="xsens_imu_black_joint" type="fixed">
    <parent link="xsens_imu_link"/>
    <child link="xsens_imu_black_link"/>
    <origin rpy="0 0 1.5707963267948966" xyz="0 0 0"/>
  </joint>
  <link name="xsens_imu_black_link">
    <visual>
      <origin rpy="0 0 0" xyz="0 0 0"/>
      <geometry>
        <mesh filename="package://bunker_unity/meshes/Sensors/xsens_IMU/xsens_black.stl" scale="0.1 0.1 0.1"/>
      </geometry>
      <material name="black"/>
    </visual>
    <inertial>
      <origin rpy="0 0 0" xyz="0 0 0"/>
      <mass value="3"/>
      <inertia ixx="0.001" ixy="0.0" ixz="0.0" iyy="0.001" iyz="0.0" izz="0.001"/>
    </inertial>
  </link>
  <joint name="xsens_imu_red_joint" type="fixed">
    <parent link="xsens_imu_link"/>
    <child link="xsens_imu_red_link"/>
    <origin rpy="0 0 1.5707963267948966" xyz="0 0 0"/>
  </joint>
  <link name="xsens_imu_red_link">
    <visual>
      <origin rpy="0 0 0" xyz="0 0 0"/>
      <geometry>
        <mesh filename="package://bunker_unity/meshes/Sensors/xsens_IMU/xsens_red.stl" scale="0.1 0.1 0.1"/>
      </geometry>
      <material name="red"/>
    </visual>
    <inertial>
      <origin rpy="0 0 0" xyz="0 0 0"/>
      <mass value="3"/>
      <inertia ixx="0.001" ixy="0.0" ixz="0.0" iyy="0.001" iyz="0.0" izz="0.001"/>
    </inertial>
  </link>
  <joint name="laser_scan_joint" type="fixed">
    <parent link="body_link"/>
    <child link="laser_scan_link"/>
    <origin rpy="0 0 0" xyz="0.18 0 1.57"/>
  </joint>
  <link name="laser_scan_link">
    <unity_sensor min_range="0.2" number_ray="360" publishing_frequency="10" scan_angle="360" scan_range="10" topic_name="/scan" type="laser_scan"/>
  </link>
  <joint name="front_left_wheel_joint" type="continuous">
    <axis xyz="0 0 1"/>
    <!-- <limit effort="10000000000" velocity="10000000000.0" lower="-50000000000" upper="50000000000" /> -->
    <parent link="body_link"/>
    <child link="front_left_wheel_link"/>
    <origin rpy="-1.5707963267948966 0 0" xyz="0.25 0.275 0.23"/>
    <unity_drive_api damping="300000000000000000" force_limit="10000000000000000000000000" stiffness="0"/>
  </joint>
  <link name="front_left_wheel_link">
    <inertial>
      <origin rpy="0 0 0" xyz="0 0 0"/>
      <mass value="0.3"/>
      <inertia ixx="0.000179574259018481" ixy="0" ixz="0" iyy="0.000179574259018481" iyz="0" izz="0.000332594534732139"/>
    </inertial>
    <collision>
      <geometry>
        <sphere radius="0.16"/>
      </geometry>
      <physics_material name="wheel"/>
    </collision>
  </link>
  <joint name="front_right_wheel_joint" type="continuous">
    <axis xyz="0 0 1"/>
    <!-- <limit effort="10000000000" velocity="10000000000.0" lower="-50000000000" upper="50000000000" /> -->
    <parent link="body_link"/>
    <child link="front_right_wheel_link"/>
    <origin rpy="-1.5707963267948966 0 0" xyz="0.25 -0.275 0.23"/>
    <unity_drive_api damping="300000000000000000" force_limit="10000000000000000000000000" stiffness="0"/>
  </joint>
  <link name="front_right_wheel_link">
    <inertial>
      <origin rpy="0 0 0" xyz="0 0 0"/>
      <mass value="0.3"/>
      <inertia ixx="0.000179574259018481" ixy="0" ixz="0" iyy="0.000179574259018481" iyz="0" izz="0.000332594534732139"/>
    </inertial>
    <collision>
      <geometry>
        <sphere radius="0.16"/>
      </geometry>
      <physics_material name="wheel"/>
    </collision>
  </link>
  <joint name="rear_left_wheel_joint" type="continuous">
    <axis xyz="0 0 1"/>
    <!-- <limit effort="10000000000" velocity="10000000000.0" lower="-50000000000" upper="50000000000" /> -->
    <parent link="body_link"/>
    <child link="rear_left_wheel_link"/>
    <origin rpy="-1.5707963267948966 0 0" xyz="-0.25 0.275 0.23"/>
    <unity_drive_api damping="300000000000000000" force_limit="10000000000000000000000000" stiffness="0"/>
  </joint>
  <link name="rear_left_wheel_link">
    <inertial>
      <origin rpy="0 0 0" xyz="0 0 0"/>
      <mass value="0.3"/>
      <inertia ixx="0.000179574259018481" ixy="0" ixz="0" iyy="0.000179574259018481" iyz="0" izz="0.000332594534732139"/>
    </inertial>
    <collision>
      <geometry>
        <sphere radius="0.16"/>
      </geometry>
      <physics_material name="wheel"/>
    </collision>
  </link>
  <joint name="rear_right_wheel_joint" type="continuous">
    <axis xyz="0 0 1"/>
    <!-- <limit effort="10000000000" velocity="10000000000.0" lower="-50000000000" upper="50000000000" /> -->
    <parent link="body_link"/>
    <child link="rear_right_wheel_link"/>
    <origin rpy="-1.5707963267948966 0 0" xyz="-0.25 -0.275 0.23"/>
    <unity_drive_api damping="300000000000000000" force_limit="10000000000000000000000000" stiffness="0"/>
  </joint>
  <link name="rear_right_wheel_link">
    <inertial>
      <origin rpy="0 0 0" xyz="0 0 0"/>
      <mass value="0.3"/>
      <inertia ixx="0.000179574259018481" ixy="0" ixz="0" iyy="0.000179574259018481" iyz="0" izz="0.000332594534732139"/>
    </inertial>
    <collision>
      <geometry>
        <sphere radius="0.16"/>
      </geometry>
      <physics_material name="wheel"/>
    </collision>
  </link>
  <link name="wheels_base_link"/>
  <joint name="wheels_base_joint" type="fixed">
    <parent link="body_link"/>
    <child link="wheels_base_link"/>
    <origin rpy="0 0 0" xyz="0 0 0.44"/>
  </joint>
  <link name="wheel1_Link">
    <gravity>1</gravity>
    <inertial>
      <origin rpy="0 0 0" xyz="0 -1.38777878078145E-17 -0.0719999999999999"/>
      <mass value="0.392034219968119"/>
      <inertia ixx="0.000179574259018481" ixy="0" ixz="0" iyy="0.000179574259018481" iyz="0" izz="0.000332594534732139"/>
    </inertial>
    <visual>
      <origin rpy="0 0 0" xyz="0 0 0"/>
      <geometry>
        <mesh filename="package://bunker_unity/meshes/Wheels/wheel1_Link.STL"/>
      </geometry>
      <material name="black"/>
    </visual>
    <!-- <collision>
        <origin
          xyz="0 0 0"
          rpy="0 0 0" />
        <geometry>
          <mesh
            filename="package://bunker_unity/meshes/Wheels/wheel1_Link.STL" />
        </geometry>
      </collision> -->
  </link>
  <joint name="wheel1_joint" type="revolute">
    <origin rpy="1.5708 0 -3.1416" xyz="0.44403 0.3495 -0.12853"/>
    <parent link="wheels_base_link"/>
    <child link="wheel1_Link"/>
    <axis xyz="0 0 1"/>
    <limit effort="0" lower="-180" upper="180" velocity="0"/>
  </joint>
  <link name="wheel1.1_Link">
    <gravity>1</gravity>
    <inertial>
      <origin rpy="0 0 0" xyz="-1.74279013442913E-08 5.87093572021469E-08 -0.0720000000000001"/>
      <mass value="0.190328287901002"/>
      <inertia ixx="0.000179574259018481" ixy="0" ixz="0" iyy="0.000179574259018481" iyz="0" izz="0.000332594534732139"/>
    </inertial>
    <visual>
      <origin rpy="0 0 0" xyz="0 0 0"/>
      <geometry>
        <mesh filename="package://bunker_unity/meshes/Wheels/wheel1.1_Link.STL"/>
      </geometry>
      <material name="black"/>
    </visual>
    <!-- <collision>
        <origin
          xyz="0 0 0"
          rpy="0 0 0" />
        <geometry>
          <mesh
            filename="package://bunker_unity/meshes/Wheels/wheel1.1_Link.STL" />
        </geometry>
      </collision> -->
  </link>
  <joint name="wheel1.1_joint" type="revolute">
    <origin rpy="1.5708 0 -3.1416" xyz="0.37551 0.3495 -0.22305"/>
    <parent link="wheels_base_link"/>
    <child link="wheel1.1_Link"/>
    <axis xyz="0 0 1"/>
    <limit effort="0" lower="-180" upper="180" velocity="0"/>
  </joint>
  <link name="wheel1.2_Link">
    <gravity>1</gravity>
    <inertial>
      <origin rpy="0 0 0" xyz="1.66533453693773E-16 4.16333634234434E-17 -0.0720000000000002"/>
      <mass value="0.271192811687251"/>
      <inertia ixx="0.000179574259018481" ixy="0" ixz="0" iyy="0.000179574259018481" iyz="0" izz="0.000332594534732139"/>
    </inertial>
    <visual>
      <origin rpy="0 0 0" xyz="0 0 0"/>
      <geometry>
        <mesh filename="package://bunker_unity/meshes/Wheels/wheel1.2_Link.STL"/>
      </geometry>
      <material name="black"/>
    </visual>
    <!-- <collision>
        <origin
          xyz="0 0 0"
          rpy="0 0 0" />
        <geometry>
          <mesh
            filename="package://bunker_unity/meshes/Wheels/wheel1.2_Link.STL" />
        </geometry>
      </collision> -->
  </link>
  <joint name="wheel1.2_joint" type="revolute">
    <origin rpy="1.5708 0 -3.1416" xyz="0.29039 0.3495 -0.28104"/>
    <parent link="wheels_base_link"/>
    <child link="wheel1.2_Link"/>
    <axis xyz="0 0 1"/>
    <limit effort="0" lower="-180" upper="180" velocity="0"/>
  </joint>
  <link name="wheel1.3_Link">
    <gravity>1</gravity>
    <inertial>
      <origin rpy="0 0 0" xyz="3.44025652177504E-05 -2.66346274915008E-05 -0.0701504149473696"/>
      <mass value="0.245835028330933"/>
      <inertia ixx="0.000179574259018481" ixy="0" ixz="0" iyy="0.000179574259018481" iyz="0" izz="0.000332594534732139"/>
    </inertial>
    <visual>
      <origin rpy="0 0 0" xyz="0 0 0"/>
      <geometry>
        <mesh filename="package://bunker_unity/meshes/Wheels/wheel1.3_Link.STL"/>
      </geometry>
      <material name="black"/>
    </visual>
    <!-- <collision>
        <origin
          xyz="0 0 0"
          rpy="0 0 0" />
        <geometry>
          <mesh
            filename="package://bunker_unity/meshes/Wheels/wheel1.3_Link.STL" />
        </geometry>
      </collision> -->
  </link>
  <joint name="wheel1.3_joint" type="revolute">
    <origin rpy="1.5708 0 -3.1416" xyz="0.29603 0.3495 -0.087"/>
    <parent link="wheels_base_link"/>
    <child link="wheel1.3_Link"/>
    <axis xyz="0 0 -1"/>
    <limit effort="0" lower="-180" upper="180" velocity="0"/>
  </joint>
  <link name="wheel2_Link">
    <gravity>1</gravity>
    <inertial>
      <origin rpy="0 0 0" xyz="-1.66533453693773E-16 0 0.072"/>
      <mass value="0.392034219968119"/>
      <inertia ixx="0.000179574259018481" ixy="0" ixz="0" iyy="0.000179574259018481" iyz="0" izz="0.000332594534732139"/>
    </inertial>
    <visual>
      <origin rpy="0 0 0" xyz="0 0 0"/>
      <geometry>
        <mesh filename="package://bunker_unity/meshes/Wheels/wheel2_Link.STL"/>
      </geometry>
      <material name="black"/>
    </visual>
    <!-- <collision>
        <origin
          xyz="0 0 0"
          rpy="0 0 0" />
        <geometry>
          <mesh
            filename="package://bunker_unity/meshes/Wheels/wheel2_Link.STL" />
        </geometry>
      </collision> -->
  </link>
  <joint name="wheel2_joint" type="revolute">
    <origin rpy="1.5708 0 -3.1416" xyz="0.44403 -0.3495 -0.12853"/>
    <parent link="wheels_base_link"/>
    <child link="wheel2_Link"/>
    <axis xyz="0 0 -1"/>
    <limit effort="0" lower="-180" upper="180" velocity="0"/>
  </joint>
  <link name="wheel2.1_Link">
    <gravity>1</gravity>
    <inertial>
      <origin rpy="0 0 0" xyz="-1.74279017328693E-08 5.87093572160247E-08 0.0720000000000002"/>
      <mass value="0.190328287901002"/>
      <inertia ixx="0.000179574259018481" ixy="0" ixz="0" iyy="0.000179574259018481" iyz="0" izz="0.000332594534732139"/>
    </inertial>
    <visual>
      <origin rpy="0 0 0" xyz="0 0 0"/>
      <geometry>
        <mesh filename="package://bunker_unity/meshes/Wheels/wheel2.1_Link.STL"/>
      </geometry>
      <material name="black"/>
    </visual>
    <!-- <collision>
        <origin
          xyz="0 0 0"
          rpy="0 0 0" />
        <geometry>
          <mesh
            filename="package://bunker_unity/meshes/Wheels/wheel2.1_Link.STL" />
        </geometry>
      </collision> -->
  </link>
  <joint name="wheel2.1_joint" type="revolute">
    <origin rpy="1.5708 0 -3.1416" xyz="0.37551 -0.3495 -0.22305"/>
    <parent link="wheels_base_link"/>
    <child link="wheel2.1_Link"/>
    <axis xyz="0 0 -1"/>
    <limit effort="0" lower="-180" upper="180" velocity="0"/>
  </joint>
  <link name="wheel2.2_Link">
    <gravity>1</gravity>
    <inertial>
      <origin rpy="0 0 0" xyz="-1.38777878078145E-16 -4.85722573273506E-17 0.0720000000000003"/>
      <mass value="0.27119281168725"/>
      <inertia ixx="0.000179574259018481" ixy="0" ixz="0" iyy="0.000179574259018481" iyz="0" izz="0.000332594534732139"/>
    </inertial>
    <visual>
      <origin rpy="0 0 0" xyz="0 0 0"/>
      <geometry>
        <mesh filename="package://bunker_unity/meshes/Wheels/wheel2.2_Link.STL"/>
      </geometry>
      <material name="black"/>
    </visual>
    <!-- <collision>
        <origin
          xyz="0 0 0"
          rpy="0 0 0" />
        <geometry>
          <mesh
            filename="package://bunker_unity/meshes/Wheels/wheel2.2_Link.STL" />
        </geometry>
      </collision> -->
  </link>
  <joint name="wheel2.2_joint" type="revolute">
    <origin rpy="1.5708 0 -3.1416" xyz="0.29039 -0.3495 -0.28104"/>
    <parent link="wheels_base_link"/>
    <child link="wheel2.2_Link"/>
    <axis xyz="0 0 -1"/>
    <limit effort="0" lower="-180" upper="180" velocity="0"/>
  </joint>
  <link name="wheel2.3_Link">
    <gravity>1</gravity>
    <inertial>
      <origin rpy="0 0 0" xyz="3.51083051564616E-05 -2.7181014665284E-05 0.0709276770204769"/>
      <mass value="0.240893303086836"/>
      <inertia ixx="0.000179574259018481" ixy="0" ixz="0" iyy="0.000179574259018481" iyz="0" izz="0.000332594534732139"/>
    </inertial>
    <visual>
      <origin rpy="0 0 0" xyz="0 0 0"/>
      <geometry>
        <mesh filename="package://bunker_unity/meshes/Wheels/wheel2.3_Link.STL"/>
      </geometry>
      <material name="black"/>
    </visual>
    <!-- <collision>
        <origin
          xyz="0 0 0"
          rpy="0 0 0" />
        <geometry>
          <mesh
            filename="package://bunker_unity/meshes/Wheels/wheel2.3_Link.STL" />
        </geometry>
      </collision> -->
  </link>
  <joint name="wheel2.3_joint" type="revolute">
    <origin rpy="1.5708 0 -3.1416" xyz="0.29603 -0.3495 -0.087"/>
    <parent link="wheels_base_link"/>
    <child link="wheel2.3_Link"/>
    <axis xyz="0 0 1"/>
    <limit effort="0" lower="-180" upper="180" velocity="0"/>
  </joint>
  <link name="wheel3_Link">
    <gravity>1</gravity>
    <inertial>
      <origin rpy="0 0 0" xyz="-1.5143569731535E-10 7.07767178198537E-16 -0.0246054820762604"/>
      <mass value="1.35828296445862"/>
      <inertia ixx="0.000179574259018481" ixy="0" ixz="0" iyy="0.000179574259018481" iyz="0" izz="0.000332594534732139"/>
    </inertial>
    <visual>
      <origin rpy="0 0 0" xyz="0 0 0"/>
      <geometry>
        <mesh filename="package://bunker_unity/meshes/Wheels/wheel3_Link.STL"/>
      </geometry>
      <material name="black"/>
    </visual>
    <!-- <collision>
        <origin
          xyz="0 0 0"
          rpy="0 0 0" />
        <geometry>
          <mesh
            filename="package://bunker_unity/meshes/Wheels/wheel3_Link.STL" />
        </geometry>
      </collision> -->
  </link>
  <joint name="wheel3_joint" type="revolute">
    <origin rpy="1.5708 0 -3.1416" xyz="-0.38871 0.295 -0.19381"/>
    <parent link="wheels_base_link"/>
    <child link="wheel3_Link"/>
    <axis xyz="0 0 -1"/>
    <limit effort="0" lower="-180" upper="180" velocity="0"/>
  </joint>
  <link name="wheel3.1_Link">
    <gravity>1</gravity>
    <inertial>
      <origin rpy="0 0 0" xyz="5.55111512312578E-17 5.55111512312578E-17 -0.0720000000000002"/>
      <mass value="0.271192811687251"/>
      <inertia ixx="0.000179574259018481" ixy="0" ixz="0" iyy="0.000179574259018481" iyz="0" izz="0.000332594534732139"/>
    </inertial>
    <visual>
      <origin rpy="0 0 0" xyz="0 0 0"/>
      <geometry>
        <mesh filename="package://bunker_unity/meshes/Wheels/wheel3.1_Link.STL"/>
      </geometry>
      <material name="black"/>
    </visual>
    <!-- <collision>
        <origin
          xyz="0 0 0"
          rpy="0 0 0" />
        <geometry>
          <mesh
            filename="package://bunker_unity/meshes/Wheels/wheel3.1_Link.STL" />
        </geometry>
      </collision> -->
  </link>
  <joint name="wheel3.1_joint" type="revolute">
    <origin rpy="1.5708 0 -3.1416" xyz="-0.23111 0.3495 -0.27671"/>
    <parent link="wheels_base_link"/>
    <child link="wheel3.1_Link"/>
    <axis xyz="0 0 1"/>
    <limit effort="0" lower="-180" upper="180" velocity="0"/>
  </joint>
  <link name="wheel3.2_Link">
    <gravity>1</gravity>
    <inertial>
      <origin rpy="0 0 0" xyz="7.58128369110489E-17 7.63278329429795E-17 -0.0720000000000003"/>
      <mass value="0.27119281168725"/>
      <inertia ixx="0.000179574259018481" ixy="0" ixz="0" iyy="0.000179574259018481" iyz="0" izz="0.000332594534732139"/>
    </inertial>
    <visual>
      <origin rpy="0 0 0" xyz="0 0 0"/>
      <geometry>
        <mesh filename="package://bunker_unity/meshes/Wheels/wheel3.2_Link.STL"/>
      </geometry>
      <material name="black"/>
    </visual>
    <!-- <collision>
        <origin
          xyz="0 0 0"
          rpy="0 0 0" />
        <geometry>
          <mesh
            filename="package://bunker_unity/meshes/Wheels/wheel3.2_Link.STL" />
        </geometry>
      </collision> -->
  </link>
  <joint name="wheel3.2_joint" type="revolute">
    <origin rpy="1.5708 0 -3.1416" xyz="0.043885 0.3495 -0.27671"/>
    <parent link="wheels_base_link"/>
    <child link="wheel3.2_Link"/>
    <axis xyz="0 0 1"/>
    <limit effort="0" lower="-180" upper="180" velocity="0"/>
  </joint>
  <link name="wheel3.3_Link">
    <gravity>1</gravity>
    <inertial>
      <origin rpy="0 0 0" xyz="1.37732703020532E-08 -5.29206664124648E-05 -0.0701501700151683"/>
      <mass value="0.245836054976119"/>
      <inertia ixx="0.000179574259018481" ixy="0" ixz="0" iyy="0.000179574259018481" iyz="0" izz="0.000332594534732139"/>
    </inertial>
    <visual>
      <origin rpy="0 0 0" xyz="0 0 0"/>
      <geometry>
        <mesh filename="package://bunker_unity/meshes/Wheels/wheel3.3_Link.STL"/>
      </geometry>
      <material name="black"/>
    </visual>
    <!-- <collision>
        <origin
          xyz="0 0 0"
          rpy="0 0 0" />
        <geometry>
          <mesh
            filename="package://bunker_unity/meshes/Wheels/wheel3.3_Link.STL" />
        </geometry>
      </collision> -->
  </link>
  <joint name="wheel3.3_joint" type="revolute">
    <origin rpy="1.5708 0 -3.1416" xyz="-0.28597 0.3495 -0.087"/>
    <parent link="wheels_base_link"/>
    <child link="wheel3.3_Link"/>
    <axis xyz="0 0 -1"/>
    <limit effort="0" lower="-180" upper="180" velocity="0"/>
  </joint>
  <link name="wheel4_Link">
    <gravity>1</gravity>
    <inertial>
      <origin rpy="0 0 0" xyz="5.55111512312578E-17 1.51436273243544E-10 0.0245928853369881"/>
      <mass value="1.35828296445862"/>
      <inertia ixx="0.000179574259018481" ixy="0" ixz="0" iyy="0.000179574259018481" iyz="0" izz="0.000332594534732139"/>
    </inertial>
    <visual>
      <origin rpy="0 0 0" xyz="0 0 0"/>
      <geometry>
        <mesh filename="package://bunker_unity/meshes/Wheels/wheel4_Link.STL"/>
      </geometry>
      <material name="black"/>
    </visual>
    <!-- <collision>
        <origin
          xyz="0 0 0"
          rpy="0 0 0" />
        <geometry>
          <mesh
            filename="package://bunker_unity/meshes/Wheels/wheel4_Link.STL" />
        </geometry>
      </collision> -->
  </link>
  <joint name="wheel4_joint" type="revolute">
    <origin rpy="1.5708 0 -3.1416" xyz="-0.38871 -0.295 -0.19381"/>
    <parent link="wheels_base_link"/>
    <child link="wheel4_Link"/>
    <axis xyz="0 0 1"/>
    <limit effort="0" lower="-180" upper="180" velocity="0"/>
  </joint>
  <link name="wheel4.1_Link">
    <gravity>1</gravity>
    <inertial>
      <origin rpy="0 0 0" xyz="-1.11022302462516E-16 -5.55111512312578E-17 0.0720000000000002"/>
      <mass value="0.271192811687251"/>
      <inertia ixx="0.000179574259018481" ixy="0" ixz="0" iyy="0.000179574259018481" iyz="0" izz="0.000332594534732139"/>
    </inertial>
    <visual>
      <origin rpy="0 0 0" xyz="0 0 0"/>
      <geometry>
        <mesh filename="package://bunker_unity/meshes/Wheels/wheel4.1_Link.STL"/>
      </geometry>
      <material name="black"/>
    </visual>
    <!-- <collision>
        <origin
          xyz="0 0 0"
          rpy="0 0 0" />
        <geometry>
          <mesh
            filename="package://bunker_unity/meshes/Wheels/wheel4.1_Link.STL" />
        </geometry>
      </collision> -->
  </link>
  <joint name="wheel4.1_joint" type="revolute">
    <origin rpy="1.5708 0 -3.1416" xyz="-0.23111 -0.3495 -0.27671"/>
    <parent link="wheels_base_link"/>
    <child link="wheel4.1_Link"/>
    <axis xyz="0 0 -1"/>
    <limit effort="0" lower="-180" upper="180" velocity="0"/>
  </joint>
  <link name="wheel4.2_Link">
    <gravity>1</gravity>
    <inertial>
      <origin rpy="0 0 0" xyz="-7.64498056873841E-17 -4.85722573273506E-17 0.0720000000000004"/>
      <mass value="0.27119281168725"/>
      <inertia ixx="0.000179574259018481" ixy="0" ixz="0" iyy="0.000179574259018481" iyz="0" izz="0.000332594534732139"/>
    </inertial>
    <visual>
      <origin rpy="0 0 0" xyz="0 0 0"/>
      <geometry>
        <mesh filename="package://bunker_unity/meshes/Wheels/wheel4.2_Link.STL"/>
      </geometry>
      <material name="black"/>
    </visual>
    <!-- <collision>
        <origin
          xyz="0 0 0"
          rpy="0 0 0" />
        <geometry>
          <mesh
            filename="package://bunker_unity/meshes/Wheels/wheel4.2_Link.STL" /> 
        </geometry>
        <surface>
          <contact>
            <collide_bitmask>0x01</collide_bitmask>
          </contact>
        </surface>
      </collision> -->
  </link>
  <joint name="wheel4.2_joint" type="revolute">
    <origin rpy="1.5708 0 -3.1416" xyz="0.043885 -0.3495 -0.27671"/>
    <parent link="wheels_base_link"/>
    <child link="wheel4.2_Link"/>
    <axis xyz="0 0 -1"/>
    <limit effort="0" lower="-180" upper="180" velocity="0"/>
  </joint>
  <link name="wheel4.3_Link">
    <inertial>
      <origin rpy="0 0 0" xyz="1.37732700244975E-08 -5.29206664124926E-05 0.0701152686893121"/>
      <mass value="0.245836054976119"/>
      <inertia ixx="0.000105264944409738" ixy="7.98231761858719E-12" ixz="6.80400273764357E-11" iyy="0.000105238344260685" iyz="-2.72106317797361E-11" izz="0.000173281039335396"/>
    </inertial>
    <visual>
      <origin rpy="0 0 0" xyz="0 0 0"/>
      <geometry>
        <mesh filename="package://bunker_unity/meshes/Wheels/wheel4.3_Link.STL"/>
      </geometry>
      <material name="black"/>
    </visual>
  </link>
  <joint name="wheel4.3_joint" type="revolute">
    <origin rpy="1.5708 0 -3.1416" xyz="-0.28597 -0.3495 -0.087"/>
    <parent link="wheels_base_link"/>
    <child link="wheel4.3_Link"/>
    <axis xyz="0 0 1"/>
    <limit effort="0" lower="-180" upper="180" velocity="0"/>
  </joint>
  <ros2_control name="Bunker" type="system">
    <hardware>
      <plugin>topic_based_ros2_control/TopicBasedSystem</plugin>
      <param name="joint_commands_topic">/Bunker/joint_command</param>
      <param name="joint_states_topic">/Bunker/joint_states</param>
      <param name="sum_wrapped_joint_states">true</param>
    </hardware>
    <joint name="front_left_wheel_joint">
      <command_interface name="velocity">
        <param name="min">-1</param>
        <param name="max">1</param>
      </command_interface>
      <state_interface name="position"/>
      <state_interface name="velocity"/>
    </joint>
    <joint name="front_right_wheel_joint">
      <command_interface name="velocity">
        <param name="min">-1</param>
        <param name="max">1</param>
      </command_interface>
      <state_interface name="position"/>
      <state_interface name="velocity"/>
    </joint>
    <joint name="rear_left_wheel_joint">
      <command_interface name="velocity">
        <param name="min">-1</param>
        <param name="max">1</param>
      </command_interface>
      <state_interface name="position"/>
      <state_interface name="velocity"/>
    </joint>
    <joint name="rear_right_wheel_joint">
      <command_interface name="velocity">
        <param name="min">-1</param>
        <param name="max">1</param>
      </command_interface>
      <state_interface name="position"/>
      <state_interface name="velocity"/>
    </joint>
    <joint name="wheel1_joint">
      <state_interface name="position"/>
    </joint>
    <joint name="wheel1.1_joint">
      <state_interface name="position"/>
    </joint>
    <joint name="wheel1.2_joint">
      <state_interface name="position"/>
    </joint>
    <joint name="wheel1.3_joint">
      <state_interface name="position"/>
    </joint>
    <joint name="wheel2_joint">
      <state_interface name="position"/>
    </joint>
    <joint name="wheel2.1_joint">
      <state_interface name="position"/>
    </joint>
    <joint name="wheel2.2_joint">
      <state_interface name="position"/>
    </joint>
    <joint name="wheel2.3_joint">
      <state_interface name="position"/>
    </joint>
    <joint name="wheel3_joint">
      <state_interface name="position"/>
    </joint>
    <joint name="wheel3.1_joint">
      <state_interface name="position"/>
    </joint>
    <joint name="wheel3.2_joint">
      <state_interface name="position"/>
    </joint>
    <joint name="wheel3.3_joint">
      <state_interface name="position"/>
    </joint>
    <joint name="wheel4_joint">
      <state_interface name="position"/>
    </joint>
    <joint name="wheel4.1_joint">
      <state_interface name="position"/>
    </joint>
    <joint name="wheel4.2_joint">
      <state_interface name="position"/>
    </joint>
    <joint name="wheel4.3_joint">
      <state_interface name="position"/>
    </joint>
  </ros2_control>
</robot>
